<?xml version="1.0" ?>
<!-- =================================================================================== -->
<!-- |    This document was autogenerated by xacro from motor_drive_webots_urdf.xacro  | -->
<!-- |    EDITING THIS FILE BY HAND IS NOT RECOMMENDED                                 | -->
<!-- =================================================================================== -->
<robot name="diff_drive" xmlns:xacro="http://www.ros.org/wiki/xacro">
  <material name="Blue">
    <color rgba="0.0 0.0 0.8 1.0"/>
  </material>
  <material name="Green">
    <color rgba="0.0 0.8 0.0 1.0"/>
  </material>
  <material name="Grey">
    <color rgba="0.7 0.7 0.7 1.0"/>
  </material>
  <material name="LightGrey">
    <color rgba="0.9 0.9 0.9 1.0"/>
  </material>
  <material name="DarkGrey">
    <color rgba="0.1 0.1 0.1 1.0"/>
  </material>
  <material name="Red">
    <color rgba="0.8 0.0 0.0 1.0"/>
  </material>
  <material name="White">
    <color rgba="1.0 1.0 1.0 1.0"/>
  </material>
  <material name="Yellow">
    <color rgba="0.96 0.88 0.14 1.0"/>
  </material>
  <material name="Black">
    <color rgba="0.0 0.0 0.0 1.0"/>
  </material>
  <material name="FlatBlack">
    <color rgba="0.09 0.09 0.09 1.0"/>
  </material>
  <material name="Orange">
    <color rgba="1.0 0.487 0.0 1.0"/>
  </material>
  <material name="pal/Orange">
    <color rgba="0.91373 0.61568 0.29411 1.0"/>
  </material>
  <material name="pal/DarkGrey">
    <color rgba="0.29804 0.29804 0.29804 1"/>
  </material>

    <!-- Base footprint -->
  <link name="base_footprint" />

  <!-- Base -->
  <link name="base_link">
    <inertial>
      <origin  xyz="-0.00000106 0.00000109 0.0000387" rpy="0 0 0"/>
      <mass value="28.26649"/>
      <inertia ixx="0.465408937" ixy="0.002160024" ixz="-0.001760255" iyy="0.483193291" iyz="-0.000655952" izz="0.550939703"/>
    </inertial>
    <visual>
      <origin xyz="0 0 0" rpy="0 0 0" />
      <geometry>
        <mesh filename="package://ros_gz_example_description/meshes/base/base.stl"/>
      </geometry>
      <material name="White"/>
    </visual>
    <collision>
      <origin xyz="0 0 0" rpy="0 0 0" />
      <geometry>
        <mesh filename="package://ros_gz_example_description/meshes/base/high_resolution/base_collision.stl"/>
      </geometry>
      <material name="White"/>
    </collision>
  </link>

  <joint name="base_footprint_joint" type="fixed">
    <origin xyz="0 0 0.0985" rpy="0 0 0"/>
    <child link="base_link"/>
    <parent link="base_footprint"/>
  </joint>


  <link name="base_antenna_left_link">
    <inertial>
      <origin xyz="0 0 0" rpy="0 0 0" />
      <mass value="0.000001"/>
      <inertia ixx="0.00000002371" ixy="0.00000006119" ixz="0.00000001179" iyy="0.00000002833" iyz="0.00000000774" izz="0.00000003849"/>
    </inertial>
    <visual>
      <origin xyz="0 0 0" rpy="0 0 0" />
      <geometry>
        <mesh filename="package://ros_gz_example_description/meshes/objects/antenna.stl"/>
      </geometry>
      <material name="Black"/>
    </visual>
    <collision>
      <origin  xyz="0 0 0.085" rpy="0 0 0"/>
      <geometry>
        <cylinder length="0.17" radius="0.005"/>
      </geometry>
      <material name="Black"/>
    </collision>
  </link>
  <joint name="base_antenna_left_joint" type="fixed">
    <origin xyz="-0.201 0.1062 0.195" rpy="0 0 0"/>
    <parent link="base_link"/>
    <child link="base_antenna_left_link"/>
  </joint>
  
  <link name="cover_link">
    <inertial>
      <origin xyz="0.22414000000 0.00002000000 0.04681000000" rpy="0 0 0" />
      <mass value="0.25821000000"/>
      <inertia ixx="0.00023719188" ixy="0.00000006119" ixz="-0.00000011799" iyy="0.00028335052" iyz="0.00000000774" izz="0.00038497063"/>
    </inertial>
    <visual>
      <origin xyz="0 0 0.13" rpy="0 0 0" />
      <geometry>
        <mesh filename="package://ros_gz_example_description/meshes/base/base_ring.stl"/>
      </geometry>
      <material name="Orange"/>
    </visual>
  </link>
  <joint name="cover_joint" type="fixed">
    <parent link="base_footprint"/>
    <child link="cover_link"/>
    <origin xyz="0 0 0" rpy="0 0 0" />
  </joint>


  <link name="base_antenna_right_link">
    <inertial>
      <origin xyz="0 0 0" rpy="0 0 0" />
      <mass value="0.000001"/>
      <inertia ixx="0.00000002371" ixy="0.00000006119" ixz="0.00000001179" iyy="0.00000002833" iyz="0.00000000774" izz="0.00000003849"/>
    </inertial>
    <visual>
      <origin xyz="0 0 0" rpy="0 0 0" />
      <geometry>
        <mesh filename="package://ros_gz_example_description/meshes/objects/antenna.stl"/>
      </geometry>
      <material name="Black"/>
    </visual>
    <collision>
      <origin xyz="0 0 0.085" rpy="0 0 0"/>
      <geometry>
        <cylinder length="0.17" radius="0.005"/>
      </geometry>
      <material name="Black"/>
    </collision>
  </link>
  <joint name="base_antenna_right_joint" type="fixed">
    <origin xyz="-0.201 -0.1062 0.195" rpy="0 0 0"/>
    <parent link="base_link"/>
    <child link="base_antenna_right_link"/>
  </joint>

  <link name="suspension_right_link">
    <inertial>
      <origin xyz="0 0 -0.02" rpy="0 0 0" />
      <mass value="10"/>
      <inertia ixx="1.0" ixy="0" ixz="0" iyy="1.0" iyz="0" izz="1.0"/>
    </inertial>
    <kinematic>0</kinematic>
    <gravity>1</gravity>
  </link>
  <joint name="suspension_right_joint" type="fixed">
    <origin xyz="0 0 0" rpy="0 0 0" />
    <axis xyz="0 0 1"/>
    <child link="suspension_right_link"/>
    <parent link="base_link"/>
  </joint>
  <link name="wheel_right_link">
    <inertial>
      <origin xyz="0 0 -0.00207" rpy="0 0 0" />
      <mass value="1.82362"/>
      <inertia ixx="0.00499743171" ixy="4.464e-08" ixz="-0.00000002245" iyy="0.00499741733" iyz="-1.64e-09" izz="0.00839239692"/>
    </inertial>
    <visual>
      <origin xyz="0 0 0" rpy="-0.0 0 0" />
      <geometry>
        <mesh filename="package://ros_gz_example_description/meshes/wheels/wheel.stl"/>
      </geometry>
      <material name="DarkGrey"/>
    </visual>
    <collision>
      <origin xyz="0 0 0" rpy="0 0 0" />
      <geometry>
        <cylinder length="0.04" radius="0.0985"/>
      </geometry>
    </collision>
  </link>
  <joint name="wheel_right_joint" type="continuous">
    <parent link="suspension_right_link"/>
    <child link="wheel_right_link"/>
    <origin xyz="0 -0.2022 0.0" rpy="-1.5707963267948966 0 0" />
    <axis xyz="0 0 1"/>
    <limit effort="6.0" velocity="10.152284263959391"/>
    <dynamics damping="1.0" friction="2.0"/>
  </joint>

  <gazebo reference="wheel_right_link">
      <material>Gazebo/DarkGrey</material>
      <selfCollide>false</selfCollide>
      <mu1 value="0.5"/>
      <mu2 value="0.5"/>
      <fdir1 value="1 0 0"/>
  </gazebo>

  <link name="suspension_left_link">
    <inertial>
      <origin xyz="0 0 -0.02" rpy="0 0 0" />
      <mass value="10"/>
      <inertia ixx="1.0" ixy="0" ixz="0" iyy="1.0" iyz="0" izz="1.0"/>
    </inertial>
    <kinematic>0</kinematic>
    <gravity>1</gravity>
  </link>
  <joint name="suspension_left_joint" type="fixed">
    <origin xyz="0 0 0" rpy="0 0 0" />
    <axis xyz="0 0 1"/>
    <child link="suspension_left_link"/>
    <parent link="base_link"/>
  </joint>
    <link name="wheel_left_link">
    <inertial>
      <origin xyz="0 0 0.00207" rpy="0 0 0" />
      <mass value="1.82362"/>
      <inertia ixx="0.00499743171" ixy="-4.464e-08" ixz="-0.00000002245" iyy="0.00499741733" iyz="1.64e-09" izz="0.00839239692"/>
    </inertial>
    <visual>
      <origin xyz="0 0 0" rpy="-3.141592653589793 0 0"/>
      <geometry>
        <mesh filename="package://ros_gz_example_description/meshes/wheels/wheel.stl"/>
      </geometry>
      <material name="DarkGrey"/>
    </visual>
    <collision>
      <origin xyz="0 0 0" rpy="0 0 0" />
      <geometry>
        <cylinder length="0.04" radius="0.0985"/>
      </geometry>
    </collision>
  </link>
  <joint name="wheel_left_joint" type="continuous">
    <parent link="suspension_left_link"/>
    <child link="wheel_left_link"/>
    <origin xyz="0 0.2022 0.0" rpy="-1.5707963267948966 0 0"/>
    <axis xyz="0 0 1"/>
    <limit effort="6.0" velocity="10.152284263959391"/>
    <dynamics damping="1.0" friction="2.0"/>
  </joint>
  
  <gazebo reference="wheel_left_link">
      <material>Gazebo/DarkGrey</material>
      <selfCollide>false</selfCollide>
      <mu1 value="0.5"/>
      <mu2 value="0.5"/>
      <fdir1 value="1 0 0"/>
  </gazebo>

  <link name="caster_front_right_1_link">
    <inertial>
      <origin xyz="-0.00634599 0.00005347 -0.02037519" rpy="0 0 0" />
      <mass value="0.05144761"/>
      <inertia ixx="0.00001513" ixy="-0.00000003" ixz="0.00000267" iyy="0.00001309" iyz="-0.00000005" izz="0.00001198"/>
    </inertial>
    <visual>
      <origin xyz="0 0 0" rpy="0 0 0" />
      <geometry>
        <mesh filename="package://ros_gz_example_description/meshes/wheels/caster_1.stl"/>
      </geometry>
      <material name="Grey"/>
    </visual>
    <!--collision>
        <origin xyz="0 0 0" rpy="0 0 0"/>
        <geometry>
          <cylinder radius="${radius}" length="${width}"/>
        </geometry>
      </collision-->
  </link>
  <joint name="caster_front_right_1_joint" type="continuous">
    <parent link="base_link"/>
    <child link="caster_front_right_1_link"/>
    <origin xyz="0.1695 -0.102 -0.0335" rpy="0 0 0" />
    <axis xyz="0 0 1"/>
  </joint>
  <link name="caster_front_right_2_link">
    <inertial>
      <origin xyz="0 0 0" rpy="0 0 0"/>
      <mass value="0.08855784"/>
      <inertia ixx="0.00001075" ixy="0" ixz="0" iyy="0.00001541" iyz="0" izz="0.00001075"/>
    </inertial>
    <visual>
      <origin xyz="0 0 0" rpy="0 0 0" />
      <geometry>
        <mesh filename="package://ros_gz_example_description/meshes/wheels/caster_2.stl"/>
      </geometry>
      <material name="DarkGrey"/>
    </visual>
    <collision>
      <origin xyz="0 0 0" rpy="0 0 0" />
      <geometry>
        <sphere radius="0.025"/>
      </geometry>
    </collision>
  </link>

    <gazebo reference="caster_front_right_2_link">
      <mu1>0.01</mu1>
      <mu2>0.01</mu2>
      <kp>1000000.0</kp>
      <kd>100.0</kd>
      <minDepth>0.002</minDepth>
      <maxVel>1.0</maxVel>
      <material>Gazebo/DarkGrey</material>
    </gazebo>

  <joint name="caster_front_right_2_joint" type="continuous">
    <parent link="caster_front_right_1_link"/>
    <child link="caster_front_right_2_link"/>
    <origin  xyz="-0.016 0.0000 -0.040" rpy="-1.5707963267948966 0 0"/>
    <axis xyz="0 0 1"/>
  </joint>
  <link name="caster_front_left_1_link">
    <inertial>
      <origin xyz="-0.00634599 0.00005347 -0.02037519" rpy="0 0 0"/>
      <mass value="0.05144761"/>
      <inertia ixx="0.00001513" ixy="-0.00000003" ixz="0.00000267" iyy="0.00001309" iyz="-0.00000005" izz="0.00001198"/>
    </inertial>
    <visual>
      <origin xyz="0 0 0" rpy="0 0 0" />
      <geometry>
        <mesh filename="package://ros_gz_example_description/meshes/wheels/caster_1.stl"/>
      </geometry>
      <material name="Grey"/>
    </visual>
    <!--collision>
        <origin xyz="0 0 0" rpy="0 0 0"/>
        <geometry>
          <cylinder radius="${radius}" length="${width}"/>
        </geometry>
      </collision-->
  </link>
  <joint name="caster_front_left_1_joint" type="continuous">
    <parent link="base_link"/>
    <child link="caster_front_left_1_link"/>
    <origin xyz="0.1695 0.102 -0.0335" rpy="0 0 0" />
    <axis xyz="0 0 1"/>
  </joint>
  <link name="caster_front_left_2_link">
    <inertial>
      <origin xyz="0 0 0" rpy="0 0 0" />
      <mass value="0.08855784"/>
      <inertia ixx="0.00001075" ixy="0" ixz="0" iyy="0.00001541" iyz="0" izz="0.00001075"/>
    </inertial>
    <visual>
      <origin xyz="0 0 0" rpy="0 0 0" />
      <geometry>
        <mesh filename="package://ros_gz_example_description/meshes/wheels/caster_2.stl"/>
      </geometry>
      <material name="DarkGrey"/>
    </visual>
    <collision>
      <origin xyz="0 0 0" rpy="0 0 0"/>
      <geometry>
        <sphere radius="0.025"/>
      </geometry>
    </collision>
  </link>

    <gazebo reference="caster_front_left_2_link">
      <mu1>0.01</mu1>
      <mu2>0.01</mu2>
      <kp>1000000.0</kp>
      <kd>100.0</kd>
      <minDepth>0.002</minDepth>
      <maxVel>1.0</maxVel>
      <material>Gazebo/DarkGrey</material>
    </gazebo>

  <joint name="caster_front_left_2_joint" type="continuous">
    <parent link="caster_front_left_1_link"/>
    <child link="caster_front_left_2_link"/>
    <origin xyz="-0.016 0.0000 -0.040" rpy="-1.5707963267948966 0 0"/>
    <axis xyz="0 0 1"/>
  </joint>
  <link name="caster_back_right_1_link">
    <inertial>
      <origin xyz="-0.00634599 0.00005347 -0.02037519" rpy="0 0 0" />
      <mass value="0.05144761"/>
      <inertia ixx="0.00001513" ixy="-0.00000003" ixz="0.00000267" iyy="0.00001309" iyz="-0.00000005" izz="0.00001198"/>
    </inertial>
    <visual>
      <origin xyz="0 0 0" rpy="0 0 0" />
      <geometry>
        <mesh filename="package://ros_gz_example_description/meshes/wheels/caster_1.stl"/>
      </geometry>
      <material name="Grey"/>
    </visual>
    <!--collision>
        <origin xyz="0 0 0" rpy="0 0 0"/>
        <geometry>
          <cylinder radius="${radius}" length="${width}"/>
        </geometry>
      </collision-->
  </link>
  <joint name="caster_back_right_1_joint" type="continuous">
    <parent link="base_link"/>
    <child link="caster_back_right_1_link"/>
    <origin xyz="-0.17350000000000002 -0.102 -0.0335" rpy="0 0 0" />
    <axis xyz="0 0 1"/>
  </joint>
  <link name="caster_back_right_2_link">
    <inertial>
      <origin xyz="0 0 0" rpy="0 0 0" />
      <mass value="0.08855784"/>
      <inertia ixx="0.00001075" ixy="0" ixz="0" iyy="0.00001541" iyz="0" izz="0.00001075"/>
    </inertial>
    <visual>
      <origin xyz="0 0 0" rpy="0 0 0" />
      <geometry>
        <mesh filename="package://ros_gz_example_description/meshes/wheels/caster_2.stl"/>
      </geometry>
      <material name="DarkGrey"/>
    </visual>
    <collision>
      <origin xyz="0 0 0" rpy="0 0 0" />
      <geometry>
        <sphere radius="0.025"/>
      </geometry>
    </collision>
  </link>

  <joint name="caster_back_right_2_joint" type="continuous">
    <parent link="caster_back_right_1_link"/>
    <child link="caster_back_right_2_link"/>
    <origin xyz="-0.016 0.0000 -0.040" rpy="-1.5707963267948966 0 0"/>
    <axis xyz="0 0 1"/>
  </joint>
    <gazebo reference="caster_back_right_2_link">
      <mu1>0.01</mu1>
      <mu2>0.01</mu2>
      <kp>1000000.0</kp>
      <kd>100.0</kd>
      <minDepth>0.002</minDepth>
      <maxVel>1.0</maxVel>
      <material>Gazebo/DarkGrey</material>
    </gazebo>
  <link name="caster_back_left_1_link">
    <inertial>
      <origin xyz="-0.00634599 0.00005347 -0.02037519" rpy="0 0 0" />
      <mass value="0.05144761"/>
      <inertia ixx="0.00001513" ixy="-0.00000003" ixz="0.00000267" iyy="0.00001309" iyz="-0.00000005" izz="0.00001198"/>
    </inertial>
    <visual>
      <origin xyz="0 0 0" rpy="0 0 0"/>
      <geometry>
        <mesh filename="package://ros_gz_example_description/meshes/wheels/caster_1.stl"/>
      </geometry>
      <material name="Grey"/>
    </visual>
    <!--collision>
        <origin xyz="0 0 0" rpy="0 0 0"/>
        <geometry>
          <cylinder radius="${radius}" length="${width}"/>
        </geometry>
      </collision-->
  </link>
  <joint name="caster_back_left_1_joint" type="continuous">
    <parent link="base_link"/>
    <child link="caster_back_left_1_link"/>
    <origin xyz="-0.17350000000000002 0.102 -0.0335" rpy="0 0 0" />
    <axis xyz="0 0 1"/>
  </joint>
  <link name="caster_back_left_2_link">
    <inertial>
      <origin xyz="0 0 0" rpy="0 0 0" />
      <mass value="0.08855784"/>
      <inertia ixx="0.00001075" ixy="0" ixz="0" iyy="0.00001541" iyz="0" izz="0.00001075"/>
    </inertial>
    <visual>
      <origin xyz="0 0 0" rpy="0 0 0" />
      <geometry>
        <mesh filename="package://ros_gz_example_description/meshes/wheels/caster_2.stl"/>
      </geometry>
      <material name="DarkGrey"/>
    </visual>
    <collision>
      <origin xyz="0 0 0" rpy="0 0 0"/>
      <geometry>
        <sphere radius="0.025"/>
      </geometry>
    </collision>
  </link>
    <gazebo reference="caster_back_left_2_link">
      <mu1>0.01</mu1>
      <mu2>0.01</mu2>
      <kp>1000000.0</kp>
      <kd>100.0</kd>
      <minDepth>0.002</minDepth>
      <maxVel>1.0</maxVel>
      <material>Gazebo/DarkGrey</material>
    </gazebo>

  <joint name="caster_back_left_2_joint" type="continuous">
    <parent link="caster_back_left_1_link"/>
    <child link="caster_back_left_2_link"/>
    <origin xyz="-0.016 0.0000 -0.040" rpy="-1.5707963267948966 0 0" />
    <axis xyz="0 0 1"/>
  </joint>
  <!-- Theoretic FOV = 220 -->
  <link name="hokuyo_laser" type="fixed">
    <inertial>
      <origin xyz="0.272 0 -0.04480000000" rpy="0 0 0" />
      <mass value="0.22963000000"/>
      <inertia ixx="0.00003393164" ixy="0.00000064943" ixz="0.00000000000" iyy="0.00001849658" iyz="0.00000000000" izz="0.00005027615"/>
    </inertial>
    <visual>
      <origin xyz="0 0 0" rpy="0 0 0" />
      <geometry>
        <mesh filename="package://ros_gz_example_description/meshes/sensors/hokuyo_urg_04lx_ug01.stl"/>
        <!-- <cylinder radius="0.0508" length="0.055"/> -->
      </geometry>
      <material name="DarkGrey"/>
    </visual>
  </link>

  <joint name="hokuyo_joint" type="fixed">
    <axis xyz="0 1 0"/>
    <origin xyz="0.272 0.0 -0.004" rpy="0 0 0"/>
    <parent link="base_link"/>
    <child link="hokuyo_laser"/>
  </joint>

    <gazebo reference="base_link">
      <material name="DarkGrey"/>
    </gazebo>

    <gazebo reference="hokuyo_laser">
      <sensor name="hokuyo" type="gpu_lidar">
        <always_on>true</always_on>
        <visualize>true</visualize>
        <update_rate>40</update_rate>
        <ignition_frame_id>hokuyo_laser</ignition_frame_id>
        <topic>scan</topic>
        <lidar>
          <scan>
            <horizontal>
              <samples>478</samples>
              <resolution>1.00000</resolution>
              <min_angle>-2.080000</min_angle>
              <max_angle>2.080000</max_angle>
            </horizontal>
          </scan>
          <range>
            <min>0.120000</min>
            <max>15.0</max>
            <resolution>0.015000</resolution>
          </range>
          <noise>
            <type>gaussian</type>
            <mean>0.0</mean>
            <stddev>0.01</stddev>
          </noise>
        </lidar>
      </sensor>
    </gazebo>

    <gazebo>
      <plugin filename="ign_ros2_control-system" name="ign_ros2_control::IgnitionROS2ControlPlugin">
        <parameters>$(find ros_gz_example_bringup)/config/controllers.yaml</parameters>
        <ros>
          <remapping>~/odom:=odom</remapping>
          <remapping>/tf:=tf</remapping>
          <remapping>/tf_static:=tf_static</remapping>
          <remapping>/diagnostics:=diagnostics</remapping>
        </ros>
      </plugin>
    </gazebo>

    <gazebo>
      <plugin filename="libignition-gazebo-pose-publisher-system.so" name="ignition::gazebo::systems::PosePublisher">
        <publish_link_pose>true</publish_link_pose>
        <publish_nested_model_pose>true</publish_nested_model_pose>
        <use_pose_vector_msg>true</use_pose_vector_msg>
        <update_frequency>50</update_frequency>
      </plugin>
    </gazebo>
    
    <!-- <gazebo>
      <plugin filename="libignition-gazebo-contact-system.so" name="ignition::gazebo::systems::Contact"></plugin>
    </gazebo>

    <gazebo>
      <plugin name='ignition::gazebo::systems::SceneBroadcaster' filename='libignition-gazebo-scene-broadcaster-system.so'/>
    </gazebo>

    <gazebo>
      <plugin filename="libignition-gazebo-sensors-system.so" name="ignition::gazebo::systems::Sensors">
        <render_engine>ogre2</render_engine>
      </plugin>
    </gazebo> -->
    
  <ros2_control name="IgnitionSystem"  type="system">
    <hardware>
        <plugin>ign_ros2_control/IgnitionSystem</plugin>
    </hardware>
    <joint name="wheel_left_joint">
      <state_interface name="position"/>
      <state_interface name="velocity"/>
      <command_interface name="velocity"/>
    </joint>
    <joint name="wheel_right_joint">
      <state_interface name="position"/>
      <state_interface name="velocity"/>
      <command_interface name="velocity"/>
    </joint>
    <joint name="caster_front_right_1_joint">
      <state_interface name="position"/>
    </joint>
    <joint name="caster_front_left_1_joint">
      <state_interface name="position"/>
    </joint>
    <joint name="caster_back_right_1_joint">
      <state_interface name="position"/>
    </joint>
    <joint name="caster_back_left_1_joint">
      <state_interface name="position"/>
    </joint>
    <joint name="caster_front_right_2_joint">
      <state_interface name="position"/>
    </joint>
    <joint name="caster_front_left_2_joint">
      <state_interface name="position"/>
    </joint>
    <joint name="caster_back_right_2_joint">
      <state_interface name="position"/>
    </joint>
    <joint name="caster_back_left_2_joint">
      <state_interface name="position"/>
    </joint>
  </ros2_control>
</robot>
